Workbook

Sheet 工质物性
A1: 工质物性
A2: 蓝字蓝底是输入。普朗特数是公式。PG25 沿用本仓库 design/calc/model.py 的 PG25_40，与 B300 冷板 v2.0 报告第 3.2 节同一行：25% 丙二醇，40 °C。计算模块没有附手册页码。本表把这一组当作体积分数 25% 的丙二醇水溶液。水一行是 v2.0 的水基线，用来对照。分配表的设计流量和设计温升只用 PG25。水只进入标明「对照」的列。本版设计要求流体温升是 B37 的 6 °C，项目要求，2026-09-30。6 °C 比 OCP 带下沿 7.5 °C 更紧，所以它不是 OCP 指标，也不是 NVIDIA 的额定温升。设计比流量在 C38，由密度、比热和 B37 用公式算出。上一版约 10 °C、1.5 L/(min·kW) 仍留在 B14 与下方对照，不作为本版设计点。
A4: 工质 | B4: 温度_C | C4: 密度_kg_m3 | D4: 比热_J_kgK | E4: 粘度_Pa_s | F4: 导热_W_mK | G4: 普朗特数 | H4: 用途
A5: PG25 | B5: 40 | C5: 1022 | D5: 3900 | E5: 0.00115 | F5: 0.452 | G5: =E5*D5/F5 | H5: 本版设计工质
A6: 水 | B6: 40 | C6: 992.2 | D6: 4179 | E6: 0.000653 | F6: 0.631 | G6: =E6*D6/F6 | H6: v2.0 水基线
A8: 能量平衡：ΔT = P / (ρ · Q · cp)。Q 为 m³/s，流量从 L/min 换成 m³/s 时除以 60000。设计体积流量_L/min = 功率_W × 60000 / (密度 × 比热 × 设计要求温升)。设计比流量 = 60×1000000 / (密度 × 比热 × 设计要求温升)，不用科学计数。设计要求温升是项目输入，见 B37，现为 6 °C。它比 OCP 下沿 7.5 °C 更紧，不是把 OCP 约 2.0 L/(min·kW) 当作设计比流量。上一版比流量 1.5 L/(min·kW) 仍在 B14，对应温升见 B20。
A10: 官方流体温升依据
A11: 2026-09-30。单颗 HBM 表面极差没有公开限值，不再把 ≤2.5 °C 当作要求。项目要求的 6 °C 也不把它恢复，6 °C 不是表面极差。OCP OAI System Liquid Cooling Guidelines，2023-03-03 更新，第 1.3 节：冷却液温升带约 7.5–12 °C；约 10 °C 对应约 1.5 L/(min·kW)，约 7.5 °C 对应约 2.0 L/(min·kW)，依据 PG25。OCP 的 7.5–12 °C、约 10 °C 和约 1.5 L/(min·kW) 留作邻值。本项目设计要求是 B37 的 6 °C，2026-09-30。6 °C 比该带下沿 7.5 °C 更紧，所以它不是 OCP 指标，也不是 NVIDIA 的额定温升。比流量用 C38 的公式。6 °C 是冷却液温升 ΔT = P / (ρ · Q · cp)，不是芯片表面极差。上一版设计点仍留在 B14、B20。蓝字是输入。
A13: 参数 | B13: 数值 | C13: 单位 | D13: 依据
A14: 上一版比流量 | B14: 1.5 | C14: L/(min·kW) | D14: OCP，OAI System Liquid Cooling Guidelines，2023-03-03 更新，第 1.3 节。约 10 °C 的典型值 1.5 LPM/kW，依据 PG25。这是上一版设计点，不是本版设计要求。本版设计要求是 B37。
A15: 比流量带下限 | B15: 1.25 | C15: L/(min·kW) | D15: 同节。对应冷却液温升上沿约 12 °C。
A16: 比流量带上限 | B16: 2 | C16: L/(min·kW) | D16: 同节。对应冷却液温升下沿约 7.5 °C。
A17: 温升带下限 | B17: 7.5 | C17: °C | D17: 同节。这是冷却液温升，不是芯片表面极差。
A18: 温升带上限 | B18: 12 | C18: °C | D18: 同节。
A19: 上一版名义温升 | B19: 10 | C19: °C | D19: 同节的典型目标，约 10 °C。上一版用它对照。本版设计要求不取这一格，取 B37。计算结果用 B20，不把 10 直接写成能量平衡。
A20: 上一版比流量对应的流体温升 | B20: =60*1000000/(C5*D5*B14) | C20: °C | D20: ΔT = 1 / (ρ · cp · 比流量 / 1000 / 60000)。分子写成 60×1000000。本行只用 PG25（C5、D5）和上一版比流量 B14，应接近第 19 行的名义 10 °C，差来自本表 ρ 与 cp。本版设计温升不取这一格，取 B37。水在同一设计温升下的比流量见 C39。
A21: 供液温度上限 | B21: 45 | C21: °C | D21: Lenovo Press LP2357，2026-08-30，表 27。供液 45 °C 时整柜流量 177 L/min，机柜压降 18.4 psi。这是供液温度，不是表面极差。
A22: HBM传感器类温度 | B22: 95 | C22: °C | D22: NVIDIA H100 PCIe，PB-11133-001 v01，表 4 与表 5。THBM 为全部 HBM 传感器的最大值，热认证取值 95 °C。GPU 的 TAVG 热认证取值 87 °C。二者都是绝对温度。
A23: 表面极差官方限值 | B23: 未公开 | C23: — | D23: 单颗表面 Tmax−Tmin，以及 4 颗或 8 颗之间的极差，公开文件中均未给出数值条款。
A25: 检索说明（2026-09-29，多方核对，不把博客当规范）。NVIDIA H100 PCIe PB-11133-001：只有传感器绝对温度，没有表面极差。JEDEC JESD238B.01 第 7.3 节：工作温度是各存储晶粒及可选逻辑晶粒的结温，主机经 TEMPERATURE 与 CHANNEL_TEMPERATURE 读取；CATTRIP 为灾难性结温跳闸。储存温度才是壳体顶面中心温度，测量指向 JESD51-2。表 71 给的是标准档与可选扩展档的绝对温度，文本中没有表面极差条款。JEDEC JESD235D 第 7.3 节：工作温度定义为 HBM 背面中心温度，扩展档的刷新见厂商数据手册。同样没有表面 Tmax−Tmin。Micron HBM3E product brief：0 °C ≤ TOPER ≤ +105 °C，是工作窗口，不是表面跨度。Samsung 公开的 HBM3 / HBM3E 页面给出带宽、容量和热阻改善百分比，数据手册需另行索取，页面上没有表面极差数字。SK hynix Newsroom 的 HBM3E 稿写散热性能约改善 10%，没有表面极差数字。OCP 上述指南约束的是冷却液温升和比流量，不是单颗 HBM 表面极差。因此分配表把表面极差官方限值写成未公开。OCP 的 7.5–12 °C 留作邻值。设计流体温升是项目要求 6 °C（B37），比 OCP 下沿更紧，不是表面极差。
A29: 上一版约 10 °C 的比流量对照
A30: 2026-09-30。这里仍是名义温升 B19 约 10 °C 的对照，不是本版设计点。比流量 = 60×1000000 / (ρ · cp · ΔT)。上一版采用的 1.5 L/(min·kW) 仍是 B14，来自 OCP 第 1.3 节对 PG25、约 10 °C 的典型值。该节的 1.25–2.0、典型 1.5 不是水的比流量，也不是 NVIDIA GB300 的额定比流量。本版设计点在第 37–38 行：温升输入是项目要求 6 °C，比 OCP 下沿 7.5 °C 更紧，比流量由公式算出。
A32: 工质 | B32: 温升_C | C32: 比流量_L_min_kW | D32: 说明
A33: PG25·等10°C对照 | B33: =B19 | C33: =60*1000000/(C5*D5*B33) | D33: 公式。同一名义温升，用 PG25 的密度和比热算出，接近 1.50。不是本版设计点。本版设计比流量在 C38。
A34: 水·等10°C对照 | B34: =B19 | C34: =60*1000000/(C6*D6*B34) | D34: 对照。同一名义约 10 °C，用水的密度和比热算出，接近 1.45。不是设计比流量，不是 OCP 给水的指标，也不是 NVIDIA GB300 的额定比流量。分配表里的水对照用的是设计温升 B37，见 C39，不再引用这一格。
A35: PG25·上一版设计点·约10℃ | B35: =B20 | C35: =B14 | D35: 上一版比流量是 C 列这一格，工质 PG25。数值来自 OCP 第 1.3 节的典型 1.5，不是 C33，也不是 C34。B 列是该比流量在 PG25 下的温升，指向 B20，约 10 °C。本版设计点不取这一行。
A37: 设计要求流体温升 | B37: 6 | C37: °C | D37: 项目要求，2026-09-30。设计流体温升 6 °C。比 OCP 第 1.3 节温升带下沿 7.5 °C（B17）更紧，所以不是 OCP 指标，也不是 NVIDIA 的额定温升。改这一格才改设计流量。这是冷却液温升 ΔT = P / (ρ · Q · cp)，不是芯片表面极差。
A38: PG25·设计比流量 | B38: =B37 | C38: =60*1000000/(C5*D5*B37) | D38: 公式。比流量 = 60×1000000 / (C5 × D5 × B37)，ρ 与 cp 取 PG25。不把 OCP 在 7.5 °C 一端的约 2.0 L/(min·kW) 写进来。设计温升是 B37 的 6 °C。
A39: 水·等6°C对照 | B39: =B37 | C39: =60*1000000/(C6*D6*B39) | D39: 对照。同一设计要求温升，用水的密度和比热算出。不是设计比流量，不是 OCP 给水的指标，也不是本版设计点。
A40: C38 是本版设计比流量，工质 PG25。分配表 F 列的体积流量按 Q = P × 60000 / (ρ · cp · B37) 闭合到 B37。C39 是水在同一温升下的比流量，分配表 M 列用它，不引用 C34。B37 是项目要求 6 °C，比 OCP 下沿 7.5 °C 更紧。B14 与 C35 只保留上一版约 10 °C。

Sheet 分配表
A1: 热量与流量分配
A2: 2026-09-30 修订。功率仍是项目输入，蓝字。设计要求冷却液温升是工质物性!B37 的 6 °C，项目要求，2026-09-30。6 °C 比 OCP 第 1.3 节温升带下沿 7.5 °C 更紧，所以它不是 OCP 指标，也不是 NVIDIA 的额定温升。这是冷却液温升 ΔT = P / (ρ · Q · cp)，不是芯片表面极差。推荐流量 = 功率_W × 60000 / (PG25 密度 × 比热 × B37)。比流量 = 60×1000000 / (密度 × 比热 × B37)。F、G 列是这一设计点。P、Q 列是上一版设计点·PG25·约10℃，比流量仍是工质物性!B14 的 1.5 L/(min·kW)。D、E 列原分配表·PG25 只保留对照。单颗表面极差官方限值 = 未公开。Lenovo 表 27 的 59/71/89/119/177 L/min 对应供液 25/30/35/40/45 °C，177 L/min 不替换；按项目 140 kW，177 L/min 的温升高于设计要求 6 °C，表 27 不另造水与 PG25 两条曲线。机柜 PG25 流量按 140 kW 和 6 °C 新算，会靠近原分配表 350–380 L/min，那是新算的结果，不是把原分配表恢复成指标。孔速 2.0 m/s、HBM 近壁 0.80 m/s 仍是项目限值。水对照：M、N 列是水·等6°C对照，不是设计点；O 列把 F 列的 PG25 设计体积流量保持不变，只改用水的密度和比热算温升。v2.0 的水基线是整板 2.0 L/min、GPU 区 1.60 L/min，在 GPU射流页，那是 1100 W 档的水候选，不是这个 6 °C 的 PG25 点。
A4: 对象 | B4: 功率来源 | C4: 功率_W | D4: 原分配表·PG25 | F4: 设计点·PG25·6°C | H4: OCP邻值温升带 | I4: 表面极差官方限值 | J4: 流路 | K4: 备注 | L4: 设计点工质 | M4: 水·等6°C对照 | O4: 水对照·固定PG25流量的水温升_C | P4: 上一版设计点·PG25·约10℃
D5: 下限_L_min | E5: 上限_L_min | F5: 流量_L_min | G5: 温升_C | M5: 流量_L_min | N5: 温升_C | P5: 流量_L_min | Q5: 温升_C
A6: 单 GPU 模组 | B6: 项目 | C6: 1400 | D6: 4 | E6: 4.2 | F6: =C6*60000/(工质物性!$C$5*工质物性!$D$5*工质物性!$B$37) | G6: =IF(F6=0,"",C6*60000/(工质物性!$C$5*F6*工质物性!$D$5)) | H6: =TEXT(工质物性!$B$17,"0.0")&"–"&TEXT(工质物性!$B$18,"0.0")&" °C" | I6: — | J6: 模组总路 | K6: Lenovo LP2357 表 10：单 GPU TGP 1100 W，官方邻值，不替换本行 1400 W。 | L6: PG25 | M6: =C6*60000/(工质物性!$C$6*工质物性!$D$6*工质物性!$B$37) | N6: =IF(M6=0,"",C6*60000/(工质物性!$C$6*M6*工质物性!$D$6)) | O6: =IF(F6=0,"",C6*60000/(工质物性!$C$6*F6*工质物性!$D$6)) | P6: =C6/1000*工质物性!$B$14 | Q6: =IF(P6=0,"",C6*60000/(工质物性!$C$5*P6*工质物性!$D$5))
A7: GPU 核心 | B7: 项目 | C7: 910 | D7: 2.4 | E7: 2.6 | F7: =C7*60000/(工质物性!$C$5*工质物性!$D$5*工质物性!$B$37) | G7: =IF(F7=0,"",C7*60000/(工质物性!$C$5*F7*工质物性!$D$5)) | H7: =TEXT(工质物性!$B$17,"0.0")&"–"&TEXT(工质物性!$B$18,"0.0")&" °C" | I7: — | J7: 冲击射流。项目孔速上限 2.0 m/s。 | K7: 几何仍是 216 孔冲击，不改成微通道。 | L7: PG25 | M7: =C7*60000/(工质物性!$C$6*工质物性!$D$6*工质物性!$B$37) | N7: =IF(M7=0,"",C7*60000/(工质物性!$C$6*M7*工质物性!$D$6)) | O7: =IF(F7=0,"",C7*60000/(工质物性!$C$6*F7*工质物性!$D$6)) | P7: =C7/1000*工质物性!$B$14 | Q7: =IF(P7=0,"",C7*60000/(工质物性!$C$5*P7*工质物性!$D$5))
A8: HBM3E 八堆 | B8: 项目 | C8: 350 | D8: 1.2 | E8: 1.4 | F8: =C8*60000/(工质物性!$C$5*工质物性!$D$5*工质物性!$B$37) | G8: =IF(F8=0,"",C8*60000/(工质物性!$C$5*F8*工质物性!$D$5)) | H8: =TEXT(工质物性!$B$17,"0.0")&"–"&TEXT(工质物性!$B$18,"0.0")&" °C" | I8: =工质物性!$B$23 | J8: 微通道，八颗并联。不是冲击孔。 | K8: 八颗之间的表面极差同样未公开。 | L8: PG25 | M8: =C8*60000/(工质物性!$C$6*工质物性!$D$6*工质物性!$B$37) | N8: =IF(M8=0,"",C8*60000/(工质物性!$C$6*M8*工质物性!$D$6)) | O8: =IF(F8=0,"",C8*60000/(工质物性!$C$6*F8*工质物性!$D$6)) | P8: =C8/1000*工质物性!$B$14 | Q8: =IF(P8=0,"",C8*60000/(工质物性!$C$5*P8*工质物性!$D$5))
A9: HBM3E 单颗 | B9: 项目 | C9: 43.7 | D9: 0.15 | E9: 0.18 | F9: =C9*60000/(工质物性!$C$5*工质物性!$D$5*工质物性!$B$37) | G9: =IF(F9=0,"",C9*60000/(工质物性!$C$5*F9*工质物性!$D$5)) | H9: =TEXT(工质物性!$B$17,"0.0")&"–"&TEXT(工质物性!$B$18,"0.0")&" °C" | I9: =工质物性!$B$23 | J9: 微通道。每颗中心进液、两侧出水。不是冲击孔。 | K9: 绝对温度：HBM 传感器类 95 °C（工质物性 B22，H100 PCIe）；供液至 45 °C（工质物性 B21）。近壁 0.80 m/s 仍是项目限值。 | L9: PG25 | M9: =C9*60000/(工质物性!$C$6*工质物性!$D$6*工质物性!$B$37) | N9: =IF(M9=0,"",C9*60000/(工质物性!$C$6*M9*工质物性!$D$6)) | O9: =IF(F9=0,"",C9*60000/(工质物性!$C$6*F9*工质物性!$D$6)) | P9: =C9/1000*工质物性!$B$14 | Q9: =IF(P9=0,"",C9*60000/(工质物性!$C$5*P9*工质物性!$D$5))
A10: 板内其他 | B10: 项目 | C10: 140 | D10: 0.3 | E10: 0.4 | F10: =C10*60000/(工质物性!$C$5*工质物性!$D$5*工质物性!$B$37) | G10: =IF(F10=0,"",C10*60000/(工质物性!$C$5*F10*工质物性!$D$5)) | H10: =TEXT(工质物性!$B$17,"0.0")&"–"&TEXT(工质物性!$B$18,"0.0")&" °C" | I10: — | J10: 随模组，不单开中心进液。 | K10: 项目拆分，约 140 W。 | L10: PG25 | M10: =C10*60000/(工质物性!$C$6*工质物性!$D$6*工质物性!$B$37) | N10: =IF(M10=0,"",C10*60000/(工质物性!$C$6*M10*工质物性!$D$6)) | O10: =IF(F10=0,"",C10*60000/(工质物性!$C$6*F10*工质物性!$D$6)) | P10: =C10/1000*工质物性!$B$14 | Q10: =IF(P10=0,"",C10*60000/(工质物性!$C$5*P10*工质物性!$D$5))
A11: 三路流量和 | B11: 公式 | C11: =C7+C8+C10 | D11: =D7+D8+D10 | E11: =E7+E8+E10 | F11: =F7+F8+F10 | G11: =IF(F11=0,"",C11*60000/(工质物性!$C$5*F11*工质物性!$D$5)) | H11: =TEXT(工质物性!$B$17,"0.0")&"–"&TEXT(工质物性!$B$18,"0.0")&" °C" | I11: — | J11: 核心 + 八堆 + 其他 | K11: 功率应等于模组。推荐流量按分项相加。 | L11: PG25 | M11: =M7+M8+M10 | N11: =IF(M11=0,"",C11*60000/(工质物性!$C$6*M11*工质物性!$D$6)) | O11: =IF(F11=0,"",C11*60000/(工质物性!$C$6*F11*工质物性!$D$6)) | P11: =P7+P8+P10 | Q11: =IF(P11=0,"",C11*60000/(工质物性!$C$5*P11*工质物性!$D$5))
A12: 八倍单颗 | B12: 公式 | C12: =8*C9 | D12: =8*D9 | E12: =8*E9 | F12: =8*F9 | G12: =IF(F12=0,"",C12*60000/(工质物性!$C$5*F12*工质物性!$D$5)) | H12: =TEXT(工质物性!$B$17,"0.0")&"–"&TEXT(工质物性!$B$18,"0.0")&" °C" | I12: =工质物性!$B$23 | J12: 八颗并联的流量和 | K12: 与第 8 行对照。43.7×8 与 350 W 的差保留，不抹平。 | L12: PG25 | M12: =8*M9 | N12: =IF(M12=0,"",C12*60000/(工质物性!$C$6*M12*工质物性!$D$6)) | O12: =IF(F12=0,"",C12*60000/(工质物性!$C$6*F12*工质物性!$D$6)) | P12: =8*P9 | Q12: =IF(P12=0,"",C12*60000/(工质物性!$C$5*P12*工质物性!$D$5))
A13: Grace 支路 | B13: 项目 | C13: 300 | D13: 0.8 | E13: 0.8 | F13: =C13*60000/(工质物性!$C$5*工质物性!$D$5*工质物性!$B$37) | G13: =IF(F13=0,"",C13*60000/(工质物性!$C$5*F13*工质物性!$D$5)) | H13: =TEXT(工质物性!$B$17,"0.0")&"–"&TEXT(工质物性!$B$18,"0.0")&" °C" | I13: — | J13: 沿 Y 交错槽。CPU 与 LPDDR 不新设中心进液。 | K13: 原分配表·PG25 这一路上下限都是 0.8 L/min。水基线 0.55 L/min 在 Grace 页，不是这两列。 | L13: PG25 | M13: =C13*60000/(工质物性!$C$6*工质物性!$D$6*工质物性!$B$37) | N13: =IF(M13=0,"",C13*60000/(工质物性!$C$6*M13*工质物性!$D$6)) | O13: =IF(F13=0,"",C13*60000/(工质物性!$C$6*F13*工质物性!$D$6)) | P13: =C13/1000*工质物性!$B$14 | Q13: =IF(P13=0,"",C13*60000/(工质物性!$C$5*P13*工质物性!$D$5))
A14: GB300 Superchip | B14: 项目 | C14: 3100 | D14: 8.8 | E14: 9.5 | F14: =C14*60000/(工质物性!$C$5*工质物性!$D$5*工质物性!$B$37) | G14: =IF(F14=0,"",C14*60000/(工质物性!$C$5*F14*工质物性!$D$5)) | H14: =TEXT(工质物性!$B$17,"0.0")&"–"&TEXT(工质物性!$B$18,"0.0")&" °C" | I14: — | J14: 1 路 Grace + 2 块模组 | K14: 1×300 + 2×1400 = 3100 W，项目功率。 | L14: PG25 | M14: =C14*60000/(工质物性!$C$6*工质物性!$D$6*工质物性!$B$37) | N14: =IF(M14=0,"",C14*60000/(工质物性!$C$6*M14*工质物性!$D$6)) | O14: =IF(F14=0,"",C14*60000/(工质物性!$C$6*F14*工质物性!$D$6)) | P14: =C14/1000*工质物性!$B$14 | Q14: =IF(P14=0,"",C14*60000/(工质物性!$C$5*P14*工质物性!$D$5))
A15: 计算托盘 | B15: 项目 | C15: 6200 | D15: 18 | E15: 20 | F15: =C15*60000/(工质物性!$C$5*工质物性!$D$5*工质物性!$B$37) | G15: =IF(F15=0,"",C15*60000/(工质物性!$C$5*F15*工质物性!$D$5)) | H15: =TEXT(工质物性!$B$17,"0.0")&"–"&TEXT(工质物性!$B$18,"0.0")&" °C" | I15: — | J15: 2 路 Grace + 4 块模组 | K15: 约 6.2 kW，项目功率。 | L15: PG25 | M15: =C15*60000/(工质物性!$C$6*工质物性!$D$6*工质物性!$B$37) | N15: =IF(M15=0,"",C15*60000/(工质物性!$C$6*M15*工质物性!$D$6)) | O15: =IF(F15=0,"",C15*60000/(工质物性!$C$6*F15*工质物性!$D$6)) | P15: =C15/1000*工质物性!$B$14 | Q15: =IF(P15=0,"",C15*60000/(工质物性!$C$5*P15*工质物性!$D$5))
A16: NVL72 | B16: 项目 | C16: 140000 | D16: 350 | E16: 380 | F16: =C16*60000/(工质物性!$C$5*工质物性!$D$5*工质物性!$B$37) | G16: =IF(F16=0,"",C16*60000/(工质物性!$C$5*F16*工质物性!$D$5)) | H16: =TEXT(工质物性!$B$17,"0.0")&"–"&TEXT(工质物性!$B$18,"0.0")&" °C" | I16: — | J16: 18 个计算托盘 + 9 个交换托盘，交换托盘不拆开。 | K16: 本行设计点是 PG25：项目 140 kW 按工质物性 B37 的 6 °C 闭合。算出来靠近原分配表 350–380 L/min，但是按 6 °C 新算的，不是把 D、E 列恢复成指标。上一版 1.5 L/(min·kW) 在 P、Q 列，约 10 °C，是邻值。Lenovo 表 27 的 177 L/min 是 45 °C 供液下的整柜要求流量，工质可为去离子水或 PG25，表 27 没有分开两条曲线。177 L/min 配项目 140 kW 的温升高于 6 °C，不替换本行，也不另造一条曲线。表 27 其余点 59/71/89/119 L/min 仍对应 25/30/35/40 °C。6 °C 比 OCP 下沿 7.5 °C 更紧，是项目要求，不是 OCP 或 NVIDIA 的额定温升。 | L16: PG25 | M16: =C16*60000/(工质物性!$C$6*工质物性!$D$6*工质物性!$B$37) | N16: =IF(M16=0,"",C16*60000/(工质物性!$C$6*M16*工质物性!$D$6)) | O16: =IF(F16=0,"",C16*60000/(工质物性!$C$6*F16*工质物性!$D$6)) | P16: =C16/1000*工质物性!$B$14 | Q16: =IF(P16=0,"",C16*60000/(工质物性!$C$5*P16*工质物性!$D$5))
A18: 对照
A19: 对照项 | B19: 差值 | C19: 单位 | D19: 说明
A20: 八倍单颗功率减八堆 | B20: =C12-C8 | C20: W | D20: 43.7×8 与八堆 350 W 的差。两行都保留。
A21: 八倍单颗推荐流量减八堆 | B21: =F12-F8 | C21: L/min | D21: 比流量相同，差只来自 349.6 W 与 350 W。
A22: 三路推荐流量减模组 | B22: =F11-F6 | C22: L/min | D22: 分项与模组用同一比流量时，差应为 0。
A23: 单颗推荐流量 | B23: =F9 | C23: L/min | D23: 单颗按 PG25、设计要求 B37 的 6 °C 闭合的流量。Q = P × 60000 / (ρ · cp · B37)。
A24: 单颗设计流体温升 | B24: =G9 | C24: °C | D24: ΔT = P / (ρ · Q · cp)，ρ 与 cp 取 PG25。应等于工质物性 B37 的 6 °C。6 °C 比 OCP 下沿 7.5 °C 更紧，是项目要求，不是 OCP 或 NVIDIA 的额定温升。这是冷却液温升，不是表面极差。
A25: 原分配表·PG25 单颗上沿减推荐流量 | B25: =E9-F9 | C25: L/min | D25: 原分配表单颗上沿减去本版推荐流量。原分配表流量仍更高。那一档是为了去追已经撤下的 2.5 °C，不是本版设计点。6 °C 是冷却液温升，不恢复表面极差要求。
A26: 上一版单颗流量 | B26: =P9 | C26: L/min | D26: 上一版 1.5 L/(min·kW)。温升见 Q9，约 10 °C。不是本版设计点。
A27: 流路边界：GPU 区保持冲击射流。HBM 保持微通道，每颗中心进液、两侧出水，不改成冲击孔。Grace 的 CPU 与 LPDDR 不新设中心进液。孔速上限 2.0 m/s 与 HBM 近壁 0.80 m/s 是项目限值，不是厂商表面温差条款。2026-09-30：流量按项目要求 6 °C 重算。6 °C 比 OCP 下沿 7.5 °C 更紧，不是表面极差。GPU 仍是 216 × 0.50 mm 冲击射流。HBM 仍是 7 × 0.80 mm × 2.00 mm，每颗中心进液、两侧出水。CPU 与 LPDDR 不新设中心进液。
A28: L 列是设计点工质，以上各行都是 PG25。D、E 列原分配表也是 PG25，不是水。F、G 列按项目要求 6 °C 闭合。6 °C 比 OCP 下沿 7.5 °C 更紧。P、Q 列是上一版约 10 °C、1.5 L/(min·kW)。M、N 列是水·等6°C对照：流量 = 功率_W × 60000 / (水的密度 × 比热 × 工质物性!B37)，温升用的是水的密度和比热（工质物性 C6、D6），应等于 B37。机柜一行会靠近原分配表 350–380 L/min，那不是把 D、E 列恢复成指标。O 列把 F 列的 PG25 设计体积流量保持不变，只把物性换成水以后的温升。M、N、O 都不是设计点。八倍单颗与八堆的 0.4 W 差额在水对照和上一版里同样保留。

Sheet GPU射流
A1: GPU 冲击射流
A2: 孔速 V = (流量_L/min / 60000) / (孔数 × π × 孔径_mm² / 4 / 1000000)。孔速上限 2.0 m/s 是项目限值，与 HBM 近壁 0.80 m/s 分开。原分配表·PG25 的流量仍用来校核孔速上沿。第 19、20 行是 6 °C 设计点，流量取 B12，即分配表 GPU 核心 F7，工质是 PG25。6 °C 比 OCP 下沿 7.5 °C 更紧，不是 1.5 L/(min·kW)。水基线 1.60 L/min 单独一行，是 1100 W 档的水候选，不用 PG25 物性，也不是这个 6 °C 点。流路仍是 216 孔冲击射流，不改成微通道。
A4: 孔数 | B4: 216
A5: v2.0 孔径_mm | B5: 0.5
A6: UC01b 孔径_mm | B6: 0.4
A7: 孔速上限_m_s | B7: 2
A8: 原分配表·PG25 GPU区流量下限_L_min | B8: =分配表!D7
A9: 原分配表·PG25 GPU区流量上限_L_min | B9: =分配表!E7
A10: 孔口阻力系数 | B10: 1.8
A11: 水·v2.0基线 GPU流量_L_min | B11: 1.6
A12: PG25·6°C设计流量_L_min | B12: =分配表!F7 | C12: GPU 核心。6 °C 设计点。流量取分配表 F7。孔速上限仍是 B7 的 2.0 m/s。
A13: 孔径_mm | B13: 流量_L_min | C13: 孔速_m_s | D13: 相对 2.0 m/s | E13: 雷诺数 | F13: 孔口压降_kPa | G13: 工质与说明
A14: =$B$5 | B14: =$B$8 | C14: =(B14/60000)/($B$4*PI()*(A14^2)/4/1000000) | D14: =IF(C14<=$B$7,"通过","不通过") | E14: =工质物性!$C$5*C14*(A14/1000)/工质物性!$E$5 | F14: =$B$10*工质物性!$C$5*C14^2/2/1000 | G14: PG25，v2.0 孔径，流量下沿
A15: =$B$5 | B15: =$B$9 | C15: =(B15/60000)/($B$4*PI()*(A15^2)/4/1000000) | D15: =IF(C15<=$B$7,"通过","不通过") | E15: =工质物性!$C$5*C15*(A15/1000)/工质物性!$E$5 | F15: =$B$10*工质物性!$C$5*C15^2/2/1000 | G15: PG25，v2.0 孔径，2.6 L/min 校核点
A16: =$B$6 | B16: =$B$8 | C16: =(B16/60000)/($B$4*PI()*(A16^2)/4/1000000) | D16: =IF(C16<=$B$7,"通过","不通过") | E16: =工质物性!$C$5*C16*(A16/1000)/工质物性!$E$5 | F16: =$B$10*工质物性!$C$5*C16^2/2/1000 | G16: PG25，UC01b 孔径，流量下沿
A17: =$B$6 | B17: =$B$9 | C17: =(B17/60000)/($B$4*PI()*(A17^2)/4/1000000) | D17: =IF(C17<=$B$7,"通过","不通过") | E17: =工质物性!$C$5*C17*(A17/1000)/工质物性!$E$5 | F17: =$B$10*工质物性!$C$5*C17^2/2/1000 | G17: PG25，UC01b 孔径，2.6 L/min 校核点
A18: =$B$5 | B18: =$B$11 | C18: =(B18/60000)/($B$4*PI()*(A18^2)/4/1000000) | D18: =IF(C18<=$B$7,"通过","不通过") | E18: =工质物性!$C$6*C18*(A18/1000)/工质物性!$E$6 | F18: =$B$10*工质物性!$C$6*C18^2/2/1000 | G18: 水基线，v2.0 的 1.60 L/min
A19: =$B$5 | B19: =$B$12 | C19: =(B19/60000)/($B$4*PI()*(A19^2)/4/1000000) | D19: =IF(C19<=$B$7,"通过","不通过") | E19: =工质物性!$C$5*C19*(A19/1000)/工质物性!$E$5 | F19: =$B$10*工质物性!$C$5*C19^2/2/1000 | G19: PG25，0.50 mm，6 °C 设计点。流量是 B12。
A20: =$B$6 | B20: =$B$12 | C20: =(B20/60000)/($B$4*PI()*(A20^2)/4/1000000) | D20: =IF(C20<=$B$7,"通过","不通过") | E20: =工质物性!$C$5*C20*(A20/1000)/工质物性!$E$5 | F20: =$B$10*工质物性!$C$5*C20^2/2/1000 | G20: PG25，0.40 mm，6 °C 设计点。流量是 B12。
A22: 原分配表上沿、216 孔、孔速恰好 2.0 m/s 的孔径_mm | B22: =1000*SQRT(4*($B$9/60000)/($B$4*PI()*$B$7)) | C22: 这是原分配表上沿的孔径下限。比它更小的孔，在原分配表上沿会超过 2.0 m/s。6 °C 设计流量低于原分配表上沿，孔速更小。0.40 mm 和 0.50 mm 都大于这个下限。
A24: =IF(AND(D14="通过",D15="通过",D16="通过",D17="通过",D19="通过",D20="通过"),"0.50 mm 与 0.40 mm 在原分配表流量和 6 °C 设计点流量（B12）下都不超过 2.0 m/s。冷板采用 v2.0 的 216 个 0.50 mm 冲击孔。不改成更小的孔，也不改成齿距小于 0.1 mm 的翅片。","有一档孔径在校核流量下超过 2.0 m/s。超过的那一档不采用。")
A26: Martin 1977 的面平均关联式下限是 Re = 2000。上表雷诺数都低于 2000，本版仍不使用 Martin。孔口压降远低于整板 20 kPa 上限。v2.0 的整板 3.5–5.5 kPa 是水、2.0 L/min 的基线，其中静压箱 3–5 kPa 是估值。本表不把那一档外推成 PG25 整板压降。

Sheet HBM单颗
A1: HBM 单颗 · 中心进液、两侧出水
A2: 直槽用保留截面：7 × 0.80 mm × 2.00 mm。单颗中心进液、两侧出水，每侧约 5.5 mm。八颗并联。不是冲击孔。0.15–0.18 L/min 是原分配表·PG25。设计流量按 PG25、项目要求冷却液温升 6 °C 闭合，见第 26 行（分配表 F9）。6 °C 比 OCP 下沿 7.5 °C 更紧。不再按 1.5 L/(min·kW)，也不再按 2.5 °C 反算。表面极差官方限值未公开，6 °C 不恢复 ≤2.5 °C，也不是表面极差。近壁 0.80 m/s 仍是项目限值。能量平衡温升 = 功率 × 60000 / (密度 × 流量 × 比热)，密度和比热取 PG25。半热量除以半流量得到同一个温升。E 列用第 26 行 B26 的 6 °C 设计流量重算流速和压降，不是原分配表流量。
A4: 槽数 | B4: 7
A5: 槽宽_mm | B5: 0.8
A6: 槽高_mm | B6: 2
A7: 肋宽_mm | B7: 0.8
A8: 岸宽_mm | B8: 0.3
A9: 列宽_mm | B9: 11
A10: 单颗功率_W | B10: =分配表!C9
A11: 原分配表·PG25 流量下限_L_min | B11: =分配表!D9
A12: 原分配表·PG25 流量上限_L_min | B12: =分配表!E9
A13: 近壁流速上限_m_s | B13: 0.8
A14: 表面极差官方限值 | B14: =工质物性!B23
A15: 铜导热_W_mK | B15: 390
A16: 单颗长度_mm | B16: 11
A17: 单侧腿长_mm | B17: 5.5
A18: 假定分流阻力系数 | B18: 1.5
A20: 宽度链_mm | B20: =2*B8+B4*B5+(B4-1)*B7 | C20: =IF(ABS(B20-B9)<0.001,"闭合","不闭合")
A21: 槽深宽比 | B21: =B6/B5 | C21: 制造地板：肋 ≥ 0.30 mm，槽宽 ≥ 0.40 mm，深宽比 ≤ 5。
A22: 水力直径_mm | B22: =2*B5*B6/(B5+B6)
A23: 普朗特数 | B23: =工质物性!E5*工质物性!D5/工质物性!F5
A24: 短边比长边 | B24: =MIN(B5,B6)/MAX(B5,B6)
A25: 矩形槽 fRe | B25: =24*(1-1.3553*B24+1.9467*B24^2-1.7012*B24^3+0.9564*B24^4-0.2537*B24^5)
A26: PG25·6°C设计流量_L_min | B26: =分配表!F9 | C26: 6 °C 设计点。流量 = 分配表 F9，Q = P×60000/(ρ·cp·B37)。不再按 2.5 °C 反算流量。上一版 1.5 L/(min·kW) 在分配表 P、Q 列。
A27: PG25推荐流量下流体温升_C | B27: =IF(B26=0,"",B10*60000/(工质物性!$C$5*B26*工质物性!$D$5)) | C27: 应回到工质物性 B37 的 6.00 °C。6 °C 比 OCP 下沿 7.5 °C 更紧，是项目要求。E 列用 B26 这一流量做槽速和压降。B–D 列仍是原分配表流量。
A28: 量 | B28: PG25·低流量 | C28: PG25·中值 | D28: PG25·高流量 | E28: PG25·6°C设计点
A29: 流量_L_min | B29: =B11 | C29: =(B11+B12)/2 | D29: =B12 | E29: =B26
A30: 满截面流速_m_s | B30: =(B29/60000)/($B$4*($B$5/1000)*($B$6/1000)) | C30: =(C29/60000)/($B$4*($B$5/1000)*($B$6/1000)) | D30: =(D29/60000)/($B$4*($B$5/1000)*($B$6/1000)) | E30: =(E29/60000)/($B$4*($B$5/1000)*($B$6/1000))
A31: 腿内流速_m_s | B31: =B30/2 | C31: =C30/2 | D31: =D30/2 | E31: =E30/2
A32: 腿内流速相对 0.80 m/s | B32: =IF(B31<=$B$13,"通过","不通过") | C32: =IF(C31<=$B$13,"通过","不通过") | D32: =IF(D31<=$B$13,"通过","不通过") | E32: =IF(E31<=$B$13,"通过","不通过")
A33: 满截面流速相对 0.80 m/s | B33: =IF(B30<=$B$13,"通过","不通过") | C33: =IF(C30<=$B$13,"通过","不通过") | D33: =IF(D30<=$B$13,"通过","不通过") | E33: =IF(E30<=$B$13,"通过","不通过")
A34: 能量平衡温升_C | B34: =IF(B29=0,"",$B$10*60000/(工质物性!$C$5*B29*工质物性!$D$5)) | C34: =IF(C29=0,"",$B$10*60000/(工质物性!$C$5*C29*工质物性!$D$5)) | D34: =IF(D29=0,"",$B$10*60000/(工质物性!$C$5*D29*工质物性!$D$5)) | E34: =IF(E29=0,"",$B$10*60000/(工质物性!$C$5*E29*工质物性!$D$5))
A35: 原分配表温升相对官方带 | B35: =IF(B34<工质物性!$B$17,"低于带下沿",IF(B34>工质物性!$B$18,"高于带上沿","落在带内")) | C35: =IF(C34<工质物性!$B$17,"低于带下沿",IF(C34>工质物性!$B$18,"高于带上沿","落在带内")) | D35: =IF(D34<工质物性!$B$17,"低于带下沿",IF(D34>工质物性!$B$18,"高于带上沿","落在带内")) | E35: ="项目要求 "&TEXT(工质物性!$B$37,"0.0")&" °C，紧于OCP下沿 "&TEXT(工质物性!$B$17,"0.0")&" °C"
A36: 腿内雷诺数 | B36: =工质物性!$C$5*B31*($B$22/1000)/工质物性!$E$5 | C36: =工质物性!$C$5*C31*($B$22/1000)/工质物性!$E$5 | D36: =工质物性!$C$5*D31*($B$22/1000)/工质物性!$E$5 | E36: =工质物性!$C$5*E31*($B$22/1000)/工质物性!$E$5
A37: 格雷兹数 | B37: =($B$22/1000)/($B$17/1000)*B36*$B$23 | C37: =($B$22/1000)/($B$17/1000)*C36*$B$23 | D37: =($B$22/1000)/($B$17/1000)*D36*$B$23 | E37: =($B$22/1000)/($B$17/1000)*E36*$B$23
A38: 努塞尔数 | B38: =MAX(4,1.86*B37^(1/3)) | C38: =MAX(4,1.86*C37^(1/3)) | D38: =MAX(4,1.86*D37^(1/3)) | E38: =MAX(4,1.86*E37^(1/3))
A39: 换热系数_W_m2K | B39: =B38*工质物性!$F$5/($B$22/1000) | C39: =C38*工质物性!$F$5/($B$22/1000) | D39: =D38*工质物性!$F$5/($B$22/1000) | E39: =E38*工质物性!$F$5/($B$22/1000)
A40: 肋参数_1_m | B40: =SQRT(2*B39/($B$15*($B$7/1000))) | C40: =SQRT(2*C39/($B$15*($B$7/1000))) | D40: =SQRT(2*D39/($B$15*($B$7/1000))) | E40: =SQRT(2*E39/($B$15*($B$7/1000)))
A41: 肋效率 | B41: =TANH(B40*$B$6/1000)/(B40*$B$6/1000) | C41: =TANH(C40*$B$6/1000)/(C40*$B$6/1000) | D41: =TANH(D40*$B$6/1000)/(D40*$B$6/1000) | E41: =TANH(E40*$B$6/1000)/(E40*$B$6/1000)
A42: 每米润湿长度_m | B42: =2*($B$5/1000)+2*($B$6/1000)*B41 | C42: =2*($B$5/1000)+2*($B$6/1000)*C41 | D42: =2*($B$5/1000)+2*($B$6/1000)*D41 | E42: =2*($B$5/1000)+2*($B$6/1000)*E41
...

Sheet Grace
A1: Grace 支路
A2: 外形 200 × 120 × 8 mm 和沿 Y 交错的槽保持 v1.0。CPU 与 LPDDR 不新设中心进液，也不改成冲击孔。水力表第 26 行是原分配表·PG25 的 0.8 L/min。第 28 行是 6 °C 设计点，流量取 B24（分配表 F13），工质 PG25。6 °C 比 OCP 下沿 7.5 °C 更紧。上一版 1.5 L/(min·kW)、约 0.45 L/min 在分配表 P、Q 列，不在本页水力表。第 27 行 0.55 L/min 是水，1100 W 档留下的水基线，能量平衡用水的密度和比热（工质物性 C6、D6），不是这个 6 °C 点。孔板仍是 4 × 1.04 mm，不在本表里改孔径。
A4: 总功率_W | B4: =分配表!C13
A5: CPU功率_W | B5: 260
A6: 单侧内存功率_W | B6: 20
A7: 原分配表·PG25 流量_L_min | B7: =分配表!D13
A8: 水·v1.0基线流量_L_min | B8: 0.55
A9: CPU槽数 | B9: 48
A10: CPU槽宽_mm | B10: 0.4
A11: CPU槽深_mm | B11: 1.2
A12: CPU摩擦长度_mm | B12: 40
A13: CPU受热长度_mm | B13: 32
A14: 转弯阻力系数合计 | B14: 3
A15: 单侧内存槽数 | B15: 6
A16: 内存槽宽_mm | B16: 1.2
A17: 内存槽深_mm | B17: 0.8
A18: 内存摩擦长度_mm | B18: 78
A19: 内存受热长度_mm | B19: 70
... A23: 努塞尔数假设 | B23: 4.8
A24: PG25·6°C设计流量_L_min | B24: =分配表!F13 | C24: =IF(B24=0,"",B4*60000/(工质物性!$C$5*B24*工质物性!$D$5)) | D24: C24 是 PG25、6 °C 设计流量下的流体温升 °C，应等于工质物性 B37 的 6 °C。物性用工质物性 C5、D5。水力表第 26 行和第 31 行仍按原分配表·PG25 的 0.8 L/min。第 28 行和第 33 行用 B24 这一流量。第 27 行是水、0.55 L/min，I27 用水的密度和比热（工质物性 C6、D6）。CPU 与 LPDDR 不改中心进液。
A25: 工况 | B25: 流量_L_min | C25: CPU流量_L_min | D25: CPU流速_m_s | E25: CPU雷诺数 | F25: CPU通道压降_kPa | G25: 孔板压降_kPa | H25: 通道加孔板_kPa | I25: 整板能量平衡温升_C | J25: 管内流速_m_s
A26: PG25，原分配表 0.8 L/min | B26: =$B$7 | C26: =B26*$B$5/$B$4 | D26: =(C26/60000)/($B$9*($B$10/1000)*($B$11/1000)) | E26: =工质物性!$C$5*D26*(2*($B$10/1000)*($B$11/1000)/(($B$10+$B$11)/1000))/工质物性!$E$5 | F26: =(64/E26*($B$12/1000)/(2*($B$10/1000)*($B$11/1000)/(($B$10+$B$11)/1000))+$B$14)*工质物性!$C$5*D26^2/2/1000 | G26: =工质物性!$C$5/2*((B26/60000)/($B$22*$B$20*PI()*($B$21^2)/4/1000000))^2/1000 | H26: =F26+G26 | I26: =IF(B26=0,"",$B$4*60000/(工质物性!$C$5*B26*工质物性!$D$5)) | J26: =(B26/60000)/(PI()*(6^2)/4/1000000)
A27: 水，基线 0.55 L/min | B27: =$B$8 | C27: =B27*$B$5/$B$4 | D27: =(C27/60000)/($B$9*($B$10/1000)*($B$11/1000)) | E27: =工质物性!$C$6*D27*(2*($B$10/1000)*($B$11/1000)/(($B$10+$B$11)/1000))/工质物性!$E$6 | F27: =(64/E27*($B$12/1000)/(2*($B$10/1000)*($B$11/1000)/(($B$10+$B$11)/1000))+$B$14)*工质物性!$C$6*D27^2/2/1000 | G27: =工质物性!$C$6/2*((B27/60000)/($B$22*$B$20*PI()*($B$21^2)/4/1000000))^2/1000 | H27: =F27+G27 | I27: =IF(B27=0,"",$B$4*60000/(工质物性!$C$6*B27*工质物性!$D$6)) | J27: =(B27/60000)/(PI()*(6^2)/4/1000000)
A28: PG25，6°C设计点（流量B24） | B28: =$B$24 | C28: =B28*$B$5/$B$4 | D28: =(C28/60000)/($B$9*($B$10/1000)*($B$11/1000)) | E28: =工质物性!$C$5*D28*(2*($B$10/1000)*($B$11/1000)/(($B$10+$B$11)/1000))/工质物性!$E$5 | F28: =(64/E28*($B$12/1000)/(2*($B$10/1000)*($B$11/1000)/(($B$10+$B$11)/1000))+$B$14)*工质物性!$C$5*D28^2/2/1000 | G28: =工质物性!$C$5/2*((B28/60000)/($B$22*$B$20*PI()*($B$21^2)/4/1000000))^2/1000 | H28: =F28+G28 | I28: =IF(B28=0,"",$B$4*60000/(工质物性!$C$5*B28*工质物性!$D$5)) | J28: =(B28/60000)/(PI()*(6^2)/4/1000000)
A30: 工况 | B30: 内存流量_L_min | C30: 内存流速_m_s | D30: 内存雷诺数 | E30: 内存通道压降_kPa | F30: 对流温差_CPU_K
A31: =A26 | B31: =B26*$B$6/$B$4 | C31: =(B31/60000)/($B$15*($B$16/1000)*($B$17/1000)) | D31: =工质物性!$C$5*C31*(2*($B$16/1000)*($B$17/1000)/(($B$16+$B$17)/1000))/工质物性!$E$5 | E31: =(64/D31*($B$18/1000)/(2*($B$16/1000)*($B$17/1000)/(($B$16+$B$17)/1000))+$B$14)*工质物性!$C$5*C31^2/2/1000 | F31: =$B$5/($B$23*工质物性!$F$5/(2*($B$10/1000)*($B$11/1000)/(($B$10+$B$11)/1000))*$B$9*($B$13/1000)*(($B$10/1000)+2*($B$11/1000)))
A32: =A27 | B32: =B27*$B$6/$B$4 | C32: =(B32/60000)/($B$15*($B$16/1000)*($B$17/1000)) | D32: =工质物性!$C$6*C32*(2*($B$16/1000)*($B$17/1000)/(($B$16+$B$17)/1000))/工质物性!$E$6 | E32: =(64/D32*($B$18/1000)/(2*($B$16/1000)*($B$17/1000)/(($B$16+$B$17)/1000))+$B$14)*工质物性!$C$6*C32^2/2/1000 | F32: =$B$5/($B$23*工质物性!$F$6/(2*($B$10/1000)*($B$11/1000)/(($B$10+$B$11)/1000))*$B$9*($B$13/1000)*(($B$10/1000)+2*($B$11/1000)))
A33: =A28 | B33: =B28*$B$6/$B$4 | C33: =(B33/60000)/($B$15*($B$16/1000)*($B$17/1000)) | D33: =工质物性!$C$5*C33*(2*($B$16/1000)*($B$17/1000)/(($B$16+$B$17)/1000))/工质物性!$E$5 | E33: =(64/D33*($B$18/1000)/(2*($B$16/1000)*($B$17/1000)/(($B$16+$B$17)/1000))+$B$14)*工质物性!$C$5*C33^2/2/1000 | F33: =$B$5/($B$23*工质物性!$F$5/(2*($B$10/1000)*($B$11/1000)/(($B$10+$B$11)/1000))*$B$9*($B$13/1000)*(($B$10/1000)+2*($B$11/1000)))
A34: 通道压降用 f = 64/Re，一进一出的转弯系数合计 3，速度用槽内速度。这是 v1.0 的同一条算法。v1.0 正文里的 0.34 m/s 和 0.96 kPa 对应水、约 0.543 L/min 的能量平衡流量，不是本表 0.55 L/min 这一行。Nu = 4.8 仍是假设。孔板压降用现有 4 × 1.04 mm 正算。第 26 行原分配表若高于 20 kPa，说明这组孔在 0.8 L/min 下装不上原来的支路窗口，槽仍不改。第 28 行和第 33 行是 6 °C 设计流量，用的是 B24，不是 0.8 L/min。几何不变，CPU 与 LPDDR 不新设中心进液。第 27 行能量平衡 I27 用水的密度和比热（工质物性 C6、D6）。上一版约 0.45 L/min 和原分配表 0.8 L/min 都是 PG25；本版设计流量是 B24，对应项目要求 6 °C。

Sheet 机柜对照
A1: 机柜流量对照
A2: 设计流量按项目机柜功率与 PG25 物性，在设计要求温升 B37 的 6 °C 上闭合能量平衡：Q = P × 60000 / (ρ · cp · B37)。6 °C 比 OCP 下沿 7.5 °C 更紧，是项目要求，不是 OCP 或 NVIDIA 的额定温升。流体温升用 ΔT = P / (ρ · Q · cp)。上一版 1.5 L/(min·kW)、约 10 °C 留在第 21 行。原分配表 350–380 L/min 是 PG25 对照，不再作为要求。Lenovo Press LP2357（2026-08-30）表 27 为供液 25/30/35/40/45 °C 对应 59/71/89/119/177 L/min。177 L/min 是 45 °C 供液下的整柜要求流量，不替换。工质可为去离子水或 PG25，表 27 没有分开两条曲线，本表不另造第二条 Lenovo 曲线。按项目 140 kW，177 L/min 的温升高于设计要求 6 °C。设计流量会靠近原分配表 350–380 L/min，是按 6 °C 新算的，不是把那一列恢复成指标。水的等 6 °C 机柜流量只作对照。
A4: 机柜功率_W | B4: =分配表!C16
A5: 原分配表·PG25 流量下限_L_min | B5: =分配表!D16
A6: 原分配表·PG25 流量上限_L_min | B6: =分配表!E16
A7: Lenovo表27·工质未分开_L_min | B7: 177 | C7: 整柜要求流量，45 °C 供液。工质可为去离子水或 PG25，表 27 没有分开两条曲线。不替换，也不另造一条水或 PG25 曲线。同表还有 59/71/89/119 L/min，见下方。
A8: Lenovo 供液温度_C | B8: 45 | C8: Lenovo 行的 45 °C 只作记录。这一行不配单一工质的温升。
A9: PG25·6°C设计流量_L_min | B9: =分配表!F16 | C9: 项目 140 kW 按 PG25、工质物性 B37 的 6 °C 闭合。设计点。按 6 °C 新算，靠近原分配表 350–380 L/min，但不是把那一列恢复成指标。不是水，也不是 Lenovo 表 27。6 °C 比 OCP 下沿 7.5 °C 更紧，不是 OCP 或 NVIDIA 的额定温升。
A10: 口径 | B10: 流量_L_min | C10: 能量平衡温升_C | D10: 相对 Lenovo 177 的倍数
A11: 原分配表·PG25 下限 | B11: =B5 | C11: =IF(B11=0,"",$B$4*60000/(工质物性!$C$5*B11*工质物性!$D$5)) | D11: =B11/$B$7
A12: 原分配表·PG25 上限 | B12: =B6 | C12: =IF(B12=0,"",$B$4*60000/(工质物性!$C$5*B12*工质物性!$D$5)) | D12: =B12/$B$7
A13: 原分配表·PG25 中值 | B13: =(B5+B6)/2 | C13: =IF(B13=0,"",$B$4*60000/(工质物性!$C$5*B13*工质物性!$D$5)) | D13: =B13/$B$7
A14: Lenovo 177·工质未分开 | B14: =B7 | C14: 表27未分列工质 | D14: =B14/$B$7
A15: PG25·6°C设计点 | B15: =B9 | C15: =IF(B15=0,"",$B$4*60000/(工质物性!$C$5*B15*工质物性!$D$5)) | D15: =B15/$B$7
A16: 对照·177×PG25物性×项目功率 | B16: =B7 | C16: =IF(B16=0,"",$B$4*60000/(工质物性!$C$5*B16*工质物性!$D$5)) | D16: 对照。用 PG25、40 °C 和项目机柜功率反算，不是表 27 的温升，也不表示 177 只适用于 PG25。该温升高于设计要求 6 °C。
A17: 对照·177×水物性×项目功率 | B17: =B7 | C17: =IF(B17=0,"",$B$4*60000/(工质物性!$C$6*B17*工质物性!$D$6)) | D17: 对照。同一 177 L/min、同一项目功率，改用水的密度和比热。表 27 仍没有两条曲线。该温升同样高于设计要求 6 °C。
A18: 水·等6°C对照 | B18: =分配表!M16 | C18: =分配表!N16 | D18: 对照。项目 140 kW，水的密度和比热，温升固定为工质物性 B37 的 6 °C。不是设计点，不替换 PG25 的设计流量，也不替换 Lenovo 177。
A19: 水对照·固定PG25设计流量 | B19: =分配表!F16 | C19: =分配表!O16 | D19: 对照。体积流量保持 PG25 的 6 °C 设计点，温升改用水的密度和比热。不是设计点，不是表 27。
A20: 第 14 行的 177 L/min 不配单一工质温升，因为表 27 没有分开水和 PG25。C16 才是「若按 PG25 物性、项目 140 kW」的反算，C17 是「若按水物性」的反算，都不是表 27 上的温升，而且都高于设计要求 6 °C。第 15 行是 PG25 设计点，温升应等于工质物性 B37 的 6 °C，不是 B20。第 18 行是水·等6°C对照，只作对照。第 19 行是 PG25 设计体积流量固定后、改用水物性的温升。第 21 行是上一版约 10 °C。原分配表 350–380 L/min 是 PG25，不再当作设计要求。供液 45 °C 时表 27 还记下机柜压降 18.4 psi，本表不改写该压降。下方五档是表 27 原列，177 L/min 不替换。
A21: 上一版设计点·PG25·约10℃ | B21: =分配表!P16 | C21: =分配表!Q16 | D21: 上一版 1.5 L/(min·kW)，温升约 10 °C。不是本版设计点。不替换第 15 行，也不替换 Lenovo 177。
A23: Lenovo LP2357 表 27
A24: 供液温度_C | B24: 流量_L_min | C24: 说明
A25: 25 | B25: 59 | C25: 表 27。供液温度，不是冷却液温升。不按水与 PG25 分列，也不替换 45 °C 的 177 L/min。
A26: 30 | B26: 71 | C26: 表 27。
A27: 35 | B27: 89 | C27: 表 27。
A28: 40 | B28: 119 | C28: 表 27。
A29: =B8 | B29: =B7 | C29: 表 27 的 45 °C 档，流量指向 B7 的 177 L/min，不另写一个数。配项目 140 kW 时，PG25 反算见 C16，水反算见 C17，都高于设计要求 6 °C。表 27 不按水与 PG25 分列。
